<?xml version="1.0" encoding="utf-8"?>
<!-- This URDF was automatically created by SolidWorks to URDF Exporter! Originally created by Stephen Brawner (brawner@gmail.com) 
     Commit Version: 1.6.0-4-g7f85cfe  Build Version: 1.6.7995.38578
     For more information, please see http://wiki.ros.org/sw_urdf_exporter -->
<robot
  name="b2_description">
   <material name="black">
    <color rgba="0.0 0.0 0.0 1.0"/>
  </material>
  <material name="blue">
    <color rgba="0.0 0.0 0.8 1.0"/>
  </material>
  <material name="green">
    <color rgba="0.0 0.8 0.0 1.0"/>
  </material>
  <material name="grey">
    <color rgba="0.2 0.2 0.2 1.0"/>
  </material>
  <material name="silver">
    <color rgba="0.913725490196 0.913725490196 0.847058823529 1.0"/>
  </material>
  <material name="silver">
    <color rgba="1.0 0.423529411765 0.0392156862745 1.0"/>
  </material>
  <material name="brown">
    <color rgba="0.870588235294 0.811764705882 0.764705882353 1.0"/>
  </material>
  <material name="red">
    <color rgba="0.8 0.0 0.0 1.0"/>
  </material>
  <material name="white">
    <color rgba="1.0 1.0 1.0 1.0"/>
  </material>

  <!-- ros_control plugin -->
  <gazebo>
    <plugin filename="libgazebo_ros_control.so" name="gazebo_ros_control">
      <robotNamespace>/aliengo_gazebo</robotNamespace>
      <robotSimType>gazebo_ros_control/DefaultRobotHWSim</robotSimType>
    </plugin>
  </gazebo>
  <!-- Show the trajectory of base center. -->
  <gazebo>
    <plugin filename="libLinkPlot3DPlugin.so" name="3dplot">
      <frequency>10</frequency>
      <plot>
        <link>base</link>
        <pose>0 0 0 0 0 0</pose>
        <material>Gazebo/Yellow</material>
      </plot>
    </plugin>
  </gazebo>
  <!-- Show the trajectory of foot. You can add another trajectory about another foot. -->
  <!-- <gazebo>
        <plugin name="3dplot" filename="libLinkPlot3DPlugin.so">
            <frequency>100</frequency>
            <plot>
                <link>FL_foot</link>
                <pose>0 0 0 0 0 0</pose>
                <material>Gazebo/Green</material>
            </plot>
        </plugin>
    </gazebo> -->
  <gazebo>
    <plugin filename="libgazebo_ros_force.so" name="gazebo_ros_force">
      <bodyName>trunk</bodyName>
      <topicName>/apply_force/trunk</topicName>
    </plugin>
  </gazebo>
  <gazebo reference="imu_link">
    <gravity>true</gravity>
    <sensor name="imu_sensor" type="imu">
      <always_on>true</always_on>
      <update_rate>1000</update_rate>
      <visualize>true</visualize>
      <topic>__default_topic__</topic>
      <plugin filename="libgazebo_ros_imu_sensor.so" name="imu_plugin">
        <topicName>trunk_imu</topicName>
        <bodyName>imu_link</bodyName>
        <updateRateHZ>1000.0</updateRateHZ>
        <gaussianNoise>0.0</gaussianNoise>
        <xyzOffset>0 0 0</xyzOffset>
        <rpyOffset>0 0 0</rpyOffset>
        <frameName>imu_link</frameName>
      </plugin>
      <pose>0 0 0 0 0 0</pose>
    </sensor>
  </gazebo>
  <!-- Foot contacts. -->
  <gazebo reference="FR_calf">
    <sensor name="FR_foot_contact" type="contact">
      <update_rate>100</update_rate>
      <plugin filename="libunitreeFootContactPlugin.so" name="contactPlugin"/>
      <contact>
        <collision>FR_calf_fixed_joint_lump__FR_foot_collision_1</collision>
      </contact>
    </sensor>
  </gazebo>
  <gazebo reference="FL_calf">
    <sensor name="FL_foot_contact" type="contact">
      <update_rate>100</update_rate>
      <plugin filename="libunitreeFootContactPlugin.so" name="contactPlugin"/>
      <contact>
        <collision>FL_calf_fixed_joint_lump__FL_foot_collision_1</collision>
      </contact>
    </sensor>
  </gazebo>
  <gazebo reference="RR_calf">
    <sensor name="RR_foot_contact" type="contact">
      <update_rate>100</update_rate>
      <plugin filename="libunitreeFootContactPlugin.so" name="contactPlugin"/>
      <contact>
        <collision>RR_calf_fixed_joint_lump__RR_foot_collision_1</collision>
      </contact>
    </sensor>
  </gazebo>
  <gazebo reference="RL_calf">
    <sensor name="RL_foot_contact" type="contact">
      <update_rate>100</update_rate>
      <plugin filename="libunitreeFootContactPlugin.so" name="contactPlugin"/>
      <contact>
        <collision>RL_calf_fixed_joint_lump__RL_foot_collision_1</collision>
      </contact>
    </sensor>
  </gazebo>
  <!-- Visualization of Foot contacts. -->
  <gazebo reference="FR_foot">
    <visual>
      <plugin filename="libunitreeDrawForcePlugin.so" name="drawForcePlugin">
        <topicName>FR_foot_contact</topicName>
      </plugin>
    </visual>
  </gazebo>
  <gazebo reference="FL_foot">
    <visual>
      <plugin filename="libunitreeDrawForcePlugin.so" name="drawForcePlugin">
        <topicName>FL_foot_contact</topicName>
      </plugin>
    </visual>
  </gazebo>
  <gazebo reference="RR_foot">
    <visual>
      <plugin filename="libunitreeDrawForcePlugin.so" name="drawForcePlugin">
        <topicName>RR_foot_contact</topicName>
      </plugin>
    </visual>
  </gazebo>
  <gazebo reference="RL_foot">
    <visual>
      <plugin filename="libunitreeDrawForcePlugin.so" name="drawForcePlugin">
        <topicName>RL_foot_contact</topicName>
      </plugin>
    </visual>
  </gazebo>
  <gazebo reference="base">
    <material>Gazebo/Green</material>
    <turnGravityOff>false</turnGravityOff>
  </gazebo>
  <gazebo reference="trunk">
    <mu1>0.2</mu1>
    <mu2>0.2</mu2>
    <kp value="1000000.0"/>
    <kd value="1.0"/>
  </gazebo>
  <gazebo reference="stick_link">
    <mu1>0.2</mu1>
    <mu2>0.2</mu2>
    <material>Gazebo/White</material>
  </gazebo>
  <gazebo reference="imu_link">
    <mu1>0.2</mu1>
    <mu2>0.2</mu2>
    <material>Gazebo/Red</material>
  </gazebo>
  <!-- FL leg -->
  <gazebo reference="FL_hip">
    <mu1>0.2</mu1>
    <mu2>0.2</mu2>
    <material>Gazebo/DarkGrey</material>
  </gazebo>
  <gazebo reference="FL_thigh">
    <mu1>0.2</mu1>
    <mu2>0.2</mu2>
    <self_collide>1</self_collide>
    <material>Gazebo/DarkGrey</material>
    <kp value="1000000.0"/>
    <kd value="1.0"/>
  </gazebo>
  <gazebo reference="FL_calf">
    <mu1>0.2</mu1>
    <mu2>0.2</mu2>
    <self_collide>1</self_collide>
  </gazebo>
  <gazebo reference="FL_foot">
    <mu1>0.6</mu1>
    <mu2>0.6</mu2>
    <self_collide>1</self_collide>
    <material>Gazebo/DarkGrey</material>
    <kp value="1000000.0"/>
    <kd value="1.0"/>
  </gazebo>
  <!-- FR leg -->
  <gazebo reference="FR_hip">
    <mu1>0.2</mu1>
    <mu2>0.2</mu2>
    <material>Gazebo/DarkGrey</material>
  </gazebo>
  <gazebo reference="FR_thigh">
    <mu1>0.2</mu1>
    <mu2>0.2</mu2>
    <self_collide>1</self_collide>
    <material>Gazebo/DarkGrey</material>
    <kp value="1000000.0"/>
    <kd value="1.0"/>
  </gazebo>
  <gazebo reference="FR_calf">
    <mu1>0.2</mu1>
    <mu2>0.2</mu2>
    <self_collide>1</self_collide>
  </gazebo>
  <gazebo reference="FR_foot">
    <mu1>0.6</mu1>
    <mu2>0.6</mu2>
    <self_collide>1</self_collide>
    <material>Gazebo/DarkGrey</material>
    <kp value="1000000.0"/>
    <kd value="1.0"/>
  </gazebo>
  <!-- RL leg -->
  <gazebo reference="RL_hip">
    <mu1>0.2</mu1>
    <mu2>0.2</mu2>
    <material>Gazebo/DarkGrey</material>
  </gazebo>
  <gazebo reference="RL_thigh">
    <mu1>0.2</mu1>
    <mu2>0.2</mu2>
    <self_collide>1</self_collide>
    <material>Gazebo/DarkGrey</material>
    <kp value="1000000.0"/>
    <kd value="1.0"/>
  </gazebo>
  <gazebo reference="RL_calf">
    <mu1>0.2</mu1>
    <mu2>0.2</mu2>
    <self_collide>1</self_collide>
  </gazebo>
  <gazebo reference="RL_foot">
    <mu1>0.6</mu1>
    <mu2>0.6</mu2>
    <self_collide>1</self_collide>
    <material>Gazebo/DarkGrey</material>
    <kp value="1000000.0"/>
    <kd value="1.0"/>
  </gazebo>
  <!-- RR leg -->
  <gazebo reference="RR_hip">
    <mu1>0.2</mu1>
    <mu2>0.2</mu2>
    <material>Gazebo/DarkGrey</material>
  </gazebo>
  <gazebo reference="RR_thigh">
    <mu1>0.2</mu1>
    <mu2>0.2</mu2>
    <self_collide>1</self_collide>
    <material>Gazebo/DarkGrey</material>
    <kp value="1000000.0"/>
    <kd value="1.0"/>
  </gazebo>
  <gazebo reference="RR_calf">
    <mu1>0.2</mu1>
    <mu2>0.2</mu2>
    <self_collide>1</self_collide>
  </gazebo>
  <gazebo reference="RR_foot">
    <mu1>0.6</mu1>
    <mu2>0.6</mu2>
    <self_collide>1</self_collide>
    <material>Gazebo/DarkGrey</material>
    <kp value="1000000.0"/>
    <kd value="1.0"/>
  </gazebo>


  <link
    name="base">
    <inertial>
      <origin
        xyz="0.000458 0.005261 0.000665"
        rpy="0 0 0" />
      <mass
        value="35.86" />
      <inertia
        ixx="0.27466"
        ixy="-0.000622"
        ixz="0.00315"
        iyy="1.0618"
        iyz="-0.00139"
        izz="1.1825" />
    </inertial>
    <visual>
      <origin
        xyz="0 0 0"
        rpy="0 0 0" />
      <geometry>
        <mesh
          filename="../meshes/base.dae" />
      </geometry>
      <material
        name="">
        <color
          rgba="1 1 1 1" />
      </material>
    </visual>
    <collision>
      <origin
        xyz="0 0 0"
        rpy="0 0 0" />
        <geometry>
          <box size="0.5 0.28 0.15" />
        </geometry>
    </collision>
  </link>

   <!-- <link name="base">
    <visual>
      <origin rpy="0 0 0" xyz="0 0 0"/>
      <geometry>
        <box size="0.001 0.001 0.001"/>
      </geometry>
    </visual>
  </link>
  <joint name="floating_base" type="fixed">
    <origin rpy="0 0 0" xyz="0 0 0"/>
    <parent link="base"/>
    <child link="trunk"/>
  </joint>
  <link name="trunk">
    <visual>
      <origin rpy="0 0 0" xyz="0 0 0"/>
      <geometry>
        <mesh filename="../meshes/trunk.dae" scale="1 1 1"/>
      </geometry>
      <material name="silver"/>
    </visual>
    <collision>
      <origin rpy="0 0 0" xyz="0 0 0"/>
      <geometry>
        <box size="0.647 0.3 0.15"/>
      </geometry>
    </collision>
    <inertial>
      <origin rpy="0 0 0" xyz="0.008987 0.002243 0.003013"/>
      <mass value="25"/>
      <inertia ixx="0.183142146" ixy="-0.001379002" ixz="-0.027956055" iyy="0.756327752" iyz="0.000193774" izz="0.783777558"/>
    </inertial>
  </link> -->

  <link
    name="imu_link">
    <inertial>
      <origin
        xyz="-2.02E-17 1.73E-17 -1.39E-17"
        rpy="0 0 0" />
      <mass
        value="4.19E-15" />
      <inertia
        ixx="1.68E-27"
        ixy="1.84E-44"
        ixz="-7.35E-44"
        iyy="1.68E-27"
        iyz="-3.67E-44"
        izz="1.68E-27" />
    </inertial>
  </link>
  <joint
    name="joint_imu"
    type="fixed">
    <origin
      xyz="0 -0.02341 0.04927"
      rpy="0 0 0" />
    <parent
      link="base" />
    <child
      link="imu_link" />
    <axis
      xyz="0 0 0" />
  </joint>
  <link
    name="head_Link">
    <inertial>
      <origin
        xyz="0.33989 -0.000168 0.12029"
        rpy="0 0 0" />
      <mass
        value="3.6885" />
      <inertia
        ixx="0.026455"
        ixy="3.15E-05"
        ixz="0.00166"
        iyy="0.029221"
        iyz="-3.27E-05"
        izz="0.010918" />
    </inertial>
    <collision>
      <origin
        xyz="0.41 0 0.005"
        rpy="0 0 0" />
      <geometry>
        <box size="0.04 0.12 0.14" />
      </geometry>
    </collision>
  </link>
  <joint
    name="joint_head"
    type="fixed">
    <origin
      xyz="0 0 0"
      rpy="0 0 0" />
    <parent
      link="base" />
    <child
      link="head_Link" />
    <axis
      xyz="0 0 0" />
  </joint>
  <link
    name="tail_link">
    <inertial>
      <origin
        xyz="-0.37448 0.000488 0.006495"
        rpy="0 0 0" />
      <mass
        value="0.795" />
      <inertia
        ixx="0.0028118"
        ixy="1.95E-05"
        ixz="-7.87E-06"
        iyy="0.0047506"
        iyz="-1.57E-05"
        izz="0.0029154" />
    </inertial>
    <collision>
      <origin
        xyz="-0.405 0 0.005"
        rpy="0 0 0" />
      <geometry>
        <box size="0.025 0.12 0.14" />
      </geometry>
    </collision>
  </link>
  <joint
    name="joint_tail"
    type="fixed">
    <origin
      xyz="0 0 0"
      rpy="0 0 0" />
    <parent
      link="base" />
    <child
      link="tail_link" />
    <axis
      xyz="0 0 0" />
  </joint>
  <link
    name="FL_hip">
    <inertial>
      <origin
        xyz="-0.003841 -0.009068 0"
        rpy="0 0 0" />
      <mass
        value="2.673" />
      <inertia
        ixx="0.0033188"
        ixy="7.16E-05"
        ixz="-3.77E-07"
        iyy="0.0048743"
        iyz="4E-09"
        izz="0.0037087" />
    </inertial>
    <visual>
      <origin
        xyz="0 0 0"
        rpy="0 0 0" />
      <geometry>
        <mesh
          filename="../meshes/FL_hip.dae" />
      </geometry>
      <material
        name="">
        <color
          rgba="1 1 1 1" />
      </material>
    </visual>
    <collision>
      <origin
        xyz="0 0.12 0"
        rpy="1.5707963267948966 0 0" />
      <geometry>
        <cylinder length="0.05" radius="0.07" />
      </geometry>
    </collision>
  </link>
  <joint
    name="FL_hip_joint"
    type="revolute">
    <origin
      xyz="0.3285 0.072 0"
      rpy="0 0 0" />
    <parent
      link="base" />
    <child
      link="FL_hip" />
    <axis
      xyz="1 0 0" />
    <limit
      lower="-0.87"
      upper="0.87"
      effort="200"
      velocity="23" />
  </joint>
  <link name="FL_hip_rotor">
    <!-- <visual>
      <origin rpy="0 1.5707963267948966 0" xyz="0 0 0"/>
      <geometry>
        <cylinder length="0.02" radius="0.05"/>
      </geometry>
    </visual> -->
    <collision>
      <origin rpy="0 1.5707963267948966 0" xyz="0 0 0"/>
      <geometry>
        <cylinder length="0.02" radius="0.05"/>
      </geometry>
    </collision>
    <inertial>
      <origin rpy="0 0 0" xyz="0.0 0.0 0.0"/>
      <mass value="0.2734"/>
      <inertia ixx="0.000144463" ixy="0.0" ixz="0.0" iyy="0.000144463" iyz="0.0" izz="0.000263053"/>
    </inertial>
  </link>
  <joint name="FL_hip_rotor_joint" type="fixed">
    <origin rpy="0 0 0" xyz="0.20205 0.072 0"/>
    <parent link="base"/>
    <child link="FL_hip_rotor"/>
  </joint>
  <link
    name="FL_thigh">
    <inertial>
      <origin
        xyz="-0.006279 -0.032049 -0.057835"
        rpy="0 0 0" />
      <mass
        value="4.536" />
      <inertia
        ixx="0.062299"
        ixy="0.00087781"
        ixz="-0.0036475"
        iyy="0.061399"
        iyz="0.0083537"
        izz="0.0081997" />
    </inertial>
    <visual>
      <origin
        xyz="0 0 0"
        rpy="0 0 0" />
      <geometry>
        <mesh
          filename="../meshes/FL_thigh.dae" />
      </geometry>
      <material
        name="">
        <color
          rgba="1 1 1 1" />
      </material>
    </visual>
    <collision>
      <origin
        xyz="-0.025 0 -0.16"
        rpy="0 1.57 0" />
      <geometry>
        <box size="0.32 0.0445 0.054" />
      </geometry>
    </collision>
  </link>
  <joint
    name="FL_thigh_joint"
    type="revolute">
    <origin
      xyz="0 0.11973 0"
      rpy="0 0 0" />
    <parent
      link="FL_hip" />
    <child
      link="FL_thigh" />
    <axis
      xyz="0 1 0" />
    <limit
      lower="-0.94"
      upper="4.69"
      effort="200"
      velocity="23" />
  </joint>
  <link name="FL_thigh_rotor">
    <!-- <visual>
      <origin rpy="1.5707963267948966 0 0" xyz="0 0 0"/>
      <geometry>
        <cylinder length="0.02" radius="0.05"/>
      </geometry>
    </visual> -->
    <collision>
      <origin rpy="1.5707963267948966 0 0" xyz="0 0 0"/>
      <geometry>
        <cylinder length="0.02" radius="0.05"/>
      </geometry>
    </collision>
    <inertial>
      <origin rpy="0 0 0" xyz="0.0 0.0 0.0"/>
      <mass value="0.2734"/>
      <inertia ixx="0.000144463" ixy="0.0" ixz="0.0" iyy="0.000144463" iyz="0.0" izz="0.000263053"/>
    </inertial>
  </link>
  <joint name="FL_thigh_rotor_joint" type="fixed">
    <origin rpy="0 0 0" xyz="0 -0.00798 0"/>
    <parent link="FL_hip"/>
    <child link="FL_thigh_rotor"/>
  </joint>
  <link
    name="FL_calf">
    <inertial>
      <origin
        xyz="0.012422 0 -0.12499"
        rpy="0 0 0" />
      <mass
        value="0.404" />
      <inertia
        ixx="0.01143"
        ixy="0"
        ixz="0.000643"
        iyy="0.011534"
        iyz="0"
        izz="0.000331" />
    </inertial>
    <visual>
      <origin
        xyz="0 0 0"
        rpy="0 0 0" />
      <geometry>
        <mesh
          filename="../meshes/FL_calf.dae" />
      </geometry>
      <material
        name="">
        <color
          rgba="1 1 1 1" />
      </material>
    </visual>
    <collision>
      <origin rpy="0 1.2 0" xyz="-0.002 0 -0.03"/>
      <geometry>
        <box size="0.1 0.0245 0.018"/>
      </geometry>
    </collision>
    <collision>
      <origin rpy="0 1.35 0" xyz="0.022 0 -0.1"/>
      <geometry>
        <box size="0.1 0.0245 0.018"/>
      </geometry>
    </collision>
    <collision>
      <origin rpy="0 1.53 0" xyz="0.036 0 -0.225"/>
      <geometry>
        <box size="0.15 0.0245 0.015"/>
      </geometry>
    </collision>
    <collision>
      <origin rpy="0 2 0" xyz="0.023 0 -0.31"/>
      <geometry>
        <box size="0.05 0.028 0.035"/>
      </geometry>
    </collision>
  </link>
  <joint
    name="FL_calf_joint"
    type="revolute">
    <origin
      xyz="0 -8.6984E-05 -0.35"
      rpy="0 0 0" />
    <parent
      link="FL_thigh" />
    <child
      link="FL_calf" />
    <axis
      xyz="0 1 0" />
    <limit
      lower="-2.82"
      upper="-0.43"
      effort="320"
      velocity="14" />
  </joint>
  <link name="FL_calf_rotor">
    <!-- <visual>
      <origin rpy="1.5707963267948966 0 0" xyz="0 0 0"/>
      <geometry>
        <cylinder length="0.02" radius="0.05"/>
      </geometry>
    </visual> -->
    <collision>
      <origin rpy="1.5707963267948966 0 0" xyz="0 0 0"/>
      <geometry>
        <cylinder length="0.02" radius="0.05"/>
      </geometry>
    </collision>
    <inertial>
      <origin rpy="0 0 0" xyz="0.0 0.0 0.0"/>
      <mass value="0.2734"/>
      <inertia ixx="0.000144463" ixy="0.0" ixz="0.0" iyy="0.000144463" iyz="0.0" izz="0.000263053"/>
    </inertial>
  </link>
  <joint name="FL_calf_rotor_joint" type="fixed">
    <origin rpy="0 0 0" xyz="0 -0.05788 0"/>
    <parent link="FL_thigh"/>
    <child link="FL_calf_rotor"/>
  </joint>
  <link
    name="FL_foot">
    <inertial>
      <origin
        xyz="-0.006511 0 -0.010144"
        rpy="0 0 0" />
      <mass
        value="0.126" />
      <inertia
        ixx="3.8E-05"
        ixy="0"
        ixz="1.1E-05"
        iyy="4.1E-05"
        iyz="0"
        izz="4.2E-05" />
    </inertial>
    <collision>
      <origin
        xyz="0 0 0"
        rpy="1.57 0 0" />
      <geometry>
        <sphere radius="0.032" />
      </geometry>
    </collision>
  </link>
  <joint
    name="FL_foot_joint"
    type="fixed"
    dont_collapse="true">
    <origin
      xyz="0 0 -0.35"
      rpy="0 0 0" />
    <parent
      link="FL_calf" />
    <child
      link="FL_foot" />
  </joint>
  <link
    name="FR_hip">
    <inertial>
      <origin
        xyz="-0.009305 0.010228 0.000264"
        rpy="0 0 0" />
      <mass
        value="2.256" />
      <inertia
        ixx="0.0026431"
        ixy="-0.00019234"
        ixz="-6.76E-06"
        iyy="0.0046728"
        iyz="7.16E-06"
        izz="0.0034208" />
    </inertial>
    <visual>
      <origin
        xyz="0 0 0"
        rpy="0 0 0" />
      <geometry>
        <mesh
          filename="../meshes/FR_hip.dae" />
      </geometry>
      <material
        name="">
        <color
          rgba="1 1 1 1" />
      </material>
    </visual>
    <collision>
      <origin
        xyz="0 -0.12 0"
        rpy="1.5707963267948966 0 0" />
      <geometry>
        <cylinder length="0.05" radius="0.07" />
      </geometry>
    </collision>
  </link>
  <joint
    name="FR_hip_joint"
    type="revolute">
    <origin
      xyz="0.3285 -0.072 0"
      rpy="0 0 0" />
    <parent
      link="base" />
    <child
      link="FR_hip" />
    <axis
      xyz="1 0 0" />
    <limit
      lower="-0.87"
      upper="0.87"
      effort="200"
      velocity="23" />
  </joint>
  <link name="FR_hip_rotor">
    <!-- <visual>
      <origin rpy="0 1.5707963267948966 0" xyz="0 0 0"/>
      <geometry>
        <cylinder length="0.02" radius="0.05"/>
      </geometry>
    </visual> -->
    <collision>
      <origin rpy="0 1.5707963267948966 0" xyz="0 0 0"/>
      <geometry>
        <cylinder length="0.02" radius="0.05"/>
      </geometry>
    </collision>
    <inertial>
      <origin rpy="0 0 0" xyz="0.0 0.0 0.0"/>
      <mass value="0.2734"/>
      <inertia ixx="0.000144463" ixy="0.0" ixz="0.0" iyy="0.000144463" iyz="0.0" izz="0.000263053"/>
    </inertial>
  </link>
  <joint name="FR_hip_rotor_joint" type="fixed">
    <origin rpy="0 0 0" xyz="0.20205 -0.072 0"/>
    <parent link="base"/>
    <child link="FR_hip_rotor"/>
  </joint>
  <link
    name="FR_thigh">
    <inertial>
      <origin
        xyz="-0.006279 0.032049 -0.057835"
        rpy="0 0 0" />
      <mass
        value="4.536" />
      <inertia
        ixx="0.06229908"
        ixy="-0.000877808"
        ixz="-0.003647464"
        iyy="0.06139927"
        iyz="-0.008353671"
        izz="0.008199745" />
    </inertial>
    <visual>
      <origin
        xyz="0 0 0"
        rpy="0 0 0" />
      <geometry>
        <mesh
          filename="../meshes/FR_thigh.dae" />
      </geometry>
      <material
        name="">
        <color
          rgba="1 1 1 1" />
      </material>
    </visual>
    <collision>
      <origin rpy="0 1.57 0" xyz="-0.03 0 -0.2"/>
      <geometry>
        <box size="0.25 0.028 0.04"/>
      </geometry>
    </collision>
  </link>
  <joint
    name="FR_thigh_joint"
    type="revolute">
    <origin
      xyz="0 -0.11973 0"
      rpy="0 0 0" />
    <parent
      link="FR_hip" />
    <child
      link="FR_thigh" />
    <axis
      xyz="0 1 0" />
    <limit
      lower="-0.94"
      upper="4.69"
      effort="200"
      velocity="23" />
  </joint>
  <link name="FR_thigh_rotor">
    <!-- <visual>
      <origin rpy="1.5707963267948966 0 0" xyz="0 0 0"/>
      <geometry>
        <cylinder length="0.02" radius="0.05"/>
      </geometry>
    </visual> -->
    <collision>
      <origin rpy="1.5707963267948966 0 0" xyz="0 0 0"/>
      <geometry>
        <cylinder length="0.02" radius="0.05"/>
      </geometry>
    </collision>
    <inertial>
      <origin rpy="0 0 0" xyz="0.0 0.0 0.0"/>
      <mass value="0.2734"/>
      <inertia ixx="0.000144463" ixy="0.0" ixz="0.0" iyy="0.000144463" iyz="0.0" izz="0.000263053"/>
    </inertial>
  </link>
  <joint name="FR_thigh_rotor_joint" type="fixed">
    <origin rpy="0 0 0" xyz="0 0.00798 0"/>
    <parent link="FR_hip"/>
    <child link="FR_thigh_rotor"/>
  </joint>
  <link
    name="FR_calf">
    <inertial>
      <origin
        xyz="0.012422 0 -0.12499"
        rpy="0 0 0" />
      <mass
        value="0.404" />
      <inertia
        ixx="0.01143"
        ixy="0"
        ixz="0.000643"
        iyy="0.011534"
        iyz="0"
        izz="0.000331" />
    </inertial>
    <visual>
      <origin
        xyz="0 0 0"
        rpy="0 0 0" />
      <geometry>
        <mesh
          filename="../meshes/FR_calf.dae" />
      </geometry>
      <material
        name="">
        <color
          rgba="1 1 1 1" />
      </material>
    </visual>
    <collision>
      <origin rpy="0 1.2 0" xyz="-0.002 0 -0.03"/>
      <geometry>
        <box size="0.1 0.0245 0.018"/>
      </geometry>
    </collision>
    <collision>
      <origin rpy="0 1.35 0" xyz="0.022 0 -0.1"/>
      <geometry>
        <box size="0.1 0.0245 0.018"/>
      </geometry>
    </collision>
    <collision>
      <origin rpy="0 1.53 0" xyz="0.036 0 -0.225"/>
      <geometry>
        <box size="0.15 0.0245 0.015"/>
      </geometry>
    </collision>
    <collision>
      <origin rpy="0 2 0" xyz="0.023 0 -0.31"/>
      <geometry>
        <box size="0.05 0.028 0.035"/>
      </geometry>
    </collision>
  </link>
  <joint
    name="FR_calf_joint"
    type="revolute">
    <origin
      xyz="0 8.6986E-05 -0.35"
      rpy="0 0 0" />
    <parent
      link="FR_thigh" />
    <child
      link="FR_calf" />
    <axis
      xyz="0 1 0" />
    <limit
      lower="-2.82"
      upper="-0.43"
      effort="320"
      velocity="14" />
  </joint>
  <link name="FR_calf_rotor">
    <!-- <visual>
      <origin rpy="1.5707963267948966 0 0" xyz="0 0 0"/>
      <geometry>
        <cylinder length="0.02" radius="0.05"/>
      </geometry>
      <material name="green"/>
    </visual> -->
    <collision>
      <origin rpy="1.5707963267948966 0 0" xyz="0 0 0"/>
      <geometry>
        <cylinder length="0.02" radius="0.05"/>
      </geometry>
    </collision>
    <inertial>
      <origin rpy="0 0 0" xyz="0.0 0.0 0.0"/>
      <mass value="0.2734"/>
      <inertia ixx="0.000144463" ixy="0.0" ixz="0.0" iyy="0.000144463" iyz="0.0" izz="0.000263053"/>
    </inertial>
  </link>
  <joint name="FR_calf_rotor_joint" type="fixed">
    <origin rpy="0 0 0" xyz="0 0.05788 0"/>
    <parent link="FR_thigh"/>
    <child link="FR_calf_rotor"/>
  </joint>
  <link
    name="FR_foot">
    <inertial>
      <origin
        xyz="-0.006511 0 -0.010144"
        rpy="0 0 0" />
      <mass
        value="0.126" />
      <inertia
        ixx="3.8E-05"
        ixy="0"
        ixz="1.1E-05"
        iyy="4.1E-05"
        iyz="0"
        izz="4.2E-05" />
    </inertial>
    <collision>
      <origin
        xyz="0 0 0"
        rpy="1.57 0 0" />
      <geometry>
        <sphere radius="0.032" />
      </geometry>
    </collision>
  </link>
  <joint
    name="FR_foot_joint"
    type="fixed"
    dont_collapse="true">
    <origin
      xyz="0 0 -0.35"
      rpy="0 0 0" />
    <parent
      link="FR_calf" />
    <child
      link="FR_foot" />
  </joint>
  <link
    name="RL_hip">
    <inertial>
      <origin
        xyz="0.009305 -0.010228 0.000264"
        rpy="0 0 0" />
      <mass
        value="2.256" />
      <inertia
        ixx="0.0026431"
        ixy="-0.00019234"
        ixz="6.76E-06"
        iyy="0.0046728"
        iyz="-7.16E-06"
        izz="0.0034208" />
    </inertial>
    <visual>
      <origin
        xyz="0 0 0"
        rpy="0 0 0" />
      <geometry>
        <mesh
          filename="../meshes/RL_hip.dae" />
      </geometry>
      <material
        name="">
        <color
          rgba="1 1 1 1" />
      </material>
    </visual>
    <collision>
      <origin
        xyz="0 0.12 0"
        rpy="1.5707963267948966 0 0" />
      <geometry>
        <cylinder length="0.05" radius="0.07" />
      </geometry>
    </collision>
  </link>
  <joint
    name="RL_hip_joint"
    type="revolute">
    <origin
      xyz="-0.3285 0.072 0"
      rpy="0 0 0" />
    <parent
      link="base" />
    <child
      link="RL_hip" />
    <axis
      xyz="1 0 0" />
    <limit
      lower="-0.87"
      upper="0.87"
      effort="200"
      velocity="23" />
  </joint>
  <link name="RL_hip_rotor">
    <!-- <visual>
      <origin rpy="0 1.5707963267948966 0" xyz="0 0 0"/>
      <geometry>
        <cylinder length="0.02" radius="0.05"/>
      </geometry>
    </visual> -->
    <collision>
      <origin rpy="0 1.5707963267948966 0" xyz="0 0 0"/>
      <geometry>
        <cylinder length="0.02" radius="0.05"/>
      </geometry>
    </collision>
    <inertial>
      <origin rpy="0 0 0" xyz="0.0 0.0 0.0"/>
      <mass value="0.2734"/>
      <inertia ixx="0.000144463" ixy="0.0" ixz="0.0" iyy="0.000144463" iyz="0.0" izz="0.000263053"/>
    </inertial>
  </link>
  <joint name="RL_hip_rotor_joint" type="fixed">
    <origin rpy="0 0 0" xyz="-0.20205 0.072 0"/>
    <parent link="base"/>
    <child link="RL_hip_rotor"/>
  </joint>
  <link
    name="RL_thigh">
    <inertial>
      <origin
        xyz="-0.006279 -0.032049 -0.057835"
        rpy="0 0 0" />
      <mass
        value="4.536" />
      <inertia
        ixx="0.06229908"
        ixy="0.000877808"
        ixz="-0.003647464"
        iyy="0.06139927"
        iyz="0.008353671"
        izz="0.008199745" />
    </inertial>
    <visual>
      <origin
        xyz="0 0 0"
        rpy="0 0 0" />
      <geometry>
        <mesh
          filename="../meshes/RL_thigh.dae" />
      </geometry>
      <material
        name="">
        <color
          rgba="1 1 1 1" />
      </material>
    </visual>
    <collision>
      <origin rpy="0 1.57 0" xyz="-0.03 0 -0.2"/>
      <geometry>
        <box size="0.25 0.028 0.04"/>
      </geometry>
    </collision>
  </link>
  <joint
    name="RL_thigh_joint"
    type="revolute">
    <origin
      xyz="0 0.11973 0"
      rpy="0 0 0" />
    <parent
      link="RL_hip" />
    <child
      link="RL_thigh" />
    <axis
      xyz="0 1 0" />
    <limit
      lower="-0.94"
      upper="4.69"
      effort="200"
      velocity="23" />
  </joint>
  <link name="RL_thigh_rotor">
    <!-- <visual>
      <origin rpy="1.5707963267948966 0 0" xyz="0 0 0"/>
      <geometry>
        <cylinder length="0.02" radius="0.05"/>
      </geometry>
    </visual> -->
    <collision>
      <origin rpy="1.5707963267948966 0 0" xyz="0 0 0"/>
      <geometry>
        <cylinder length="0.02" radius="0.05"/>
      </geometry>
    </collision>
    <inertial>
      <origin rpy="0 0 0" xyz="0.0 0.0 0.0"/>
      <mass value="0.2734"/>
      <inertia ixx="0.000144463" ixy="0.0" ixz="0.0" iyy="0.000144463" iyz="0.0" izz="0.000263053"/>
    </inertial>
  </link>
  <joint name="RL_thigh_rotor_joint" type="fixed">
    <origin rpy="0 0 0" xyz="0 -0.00798 0"/>
    <parent link="RL_hip"/>
    <child link="RL_thigh_rotor"/>
  </joint>
  <link
    name="RL_calf">
    <inertial>
      <origin
        xyz="0.012422 0 -0.12499"
        rpy="0 0 0" />
      <mass
        value="0.404" />
      <inertia
        ixx="0.01143"
        ixy="0"
        ixz="0.000643"
        iyy="0.011534"
        iyz="0"
        izz="0.000331" />
    </inertial>
    <visual>
      <origin
        xyz="0 0 0"
        rpy="0 0 0" />
      <geometry>
        <mesh
          filename="../meshes/RL_calf.dae" />
      </geometry>
      <material
        name="">
        <color
          rgba="1 1 1 1" />
      </material>
    </visual>
    <collision>
      <origin rpy="0 1.2 0" xyz="-0.002 0 -0.03"/>
      <geometry>
        <box size="0.1 0.0245 0.018"/>
      </geometry>
    </collision>
    <collision>
      <origin rpy="0 1.35 0" xyz="0.022 0 -0.1"/>
      <geometry>
        <box size="0.1 0.0245 0.018"/>
      </geometry>
    </collision>
    <collision>
      <origin rpy="0 1.53 0" xyz="0.036 0 -0.225"/>
      <geometry>
        <box size="0.15 0.0245 0.015"/>
      </geometry>
    </collision>
    <collision>
      <origin rpy="0 2 0" xyz="0.023 0 -0.31"/>
      <geometry>
        <box size="0.05 0.028 0.035"/>
      </geometry>
    </collision>
  </link>
  <joint
    name="RL_calf_joint"
    type="revolute">
    <origin
      xyz="0 -8.6984E-05 -0.35"
      rpy="0 0 0" />
    <parent
      link="RL_thigh" />
    <child
      link="RL_calf" />
    <axis
      xyz="0 1 0" />
    <limit
      lower="-2.82"
      upper="-0.43"
      effort="320"
      velocity="14" />
  </joint>
  <link name="RL_calf_rotor">
    <!-- <visual>
      <origin rpy="1.5707963267948966 0 0" xyz="0 0 0"/>
      <geometry>
        <cylinder length="0.02" radius="0.05"/>
      </geometry>
    </visual> -->
    <collision>
      <origin rpy="1.5707963267948966 0 0" xyz="0 0 0"/>
      <geometry>
        <cylinder length="0.02" radius="0.05"/>
      </geometry>
    </collision>
    <inertial>
      <origin rpy="0 0 0" xyz="0.0 0.0 0.0"/>
      <mass value="0.2734"/>
      <inertia ixx="0.000144463" ixy="0.0" ixz="0.0" iyy="0.000144463" iyz="0.0" izz="0.000263053"/>
    </inertial>
  </link>
  <joint name="RL_calf_rotor_joint" type="fixed">
    <origin rpy="0 0 0" xyz="0 -0.05788 0"/>
    <parent link="RL_thigh"/>
    <child link="RL_calf_rotor"/>
  </joint>
  <link
    name="RL_foot">
    <inertial>
      <origin
        xyz="-0.006511 0 -0.010144"
        rpy="0 0 0" />
      <mass
        value="0.126" />
      <inertia
        ixx="3.8E-05"
        ixy="0"
        ixz="1.1E-05"
        iyy="4.1E-05"
        iyz="0"
        izz="4.2E-05" />
    </inertial>
    <collision>
      <origin
        xyz="0 0 0"
        rpy="1.57 0 0" />
      <geometry>
        <sphere radius="0.032" />
      </geometry>
    </collision>
  </link>
  <joint
    name="RL_foot_joint"
    type="fixed"
    dont_collapse="true">
    <origin
      xyz="0 0 -0.35"
      rpy="0 0 0" />
    <parent
      link="RL_calf" />
    <child
      link="RL_foot" />
  </joint>
  <link
    name="RR_hip">
    <inertial>
      <origin
        xyz="0.003841 0.009068 0"
        rpy="0 0 0" />
      <mass
        value="2.673" />
      <inertia
        ixx="0.0033188"
        ixy="7.16E-05"
        ixz="3.77E-07"
        iyy="0.0048743"
        iyz="-4E-09"
        izz="0.0037087" />
    </inertial>
    <visual>
      <origin
        xyz="0 0 0"
        rpy="0 0 0" />
      <geometry>
        <mesh
          filename="../meshes/RR_hip.dae" />
      </geometry>
      <material
        name="">
        <color
          rgba="1 1 1 1" />
      </material>
    </visual>
    <collision>
      <origin
        xyz="0 -0.12 0"
        rpy="1.5707963267948966 0 0" />
      <geometry>
        <cylinder length="0.05" radius="0.07" />
      </geometry>
    </collision>
  </link>
  <joint
    name="RR_hip_joint"
    type="revolute">
    <origin
      xyz="-0.3285 -0.072 0"
      rpy="0 0 0" />
    <parent
      link="base" />
    <child
      link="RR_hip" />
    <axis
      xyz="1 0 0" />
    <limit
      lower="-0.87"
      upper="0.87"
      effort="200"
      velocity="23" />
  </joint>
  <link name="RR_hip_rotor">
    <!-- <visual>
      <origin rpy="0 1.5707963267948966 0" xyz="0 0 0"/>
      <geometry>
        <cylinder length="0.02" radius="0.05"/>
      </geometry>
    </visual> -->
    <collision>
      <origin rpy="0 1.5707963267948966 0" xyz="0 0 0"/>
      <geometry>
        <cylinder length="0.02" radius="0.05"/>
      </geometry>
    </collision>
    <inertial>
      <origin rpy="0 0 0" xyz="0.0 0.0 0.0"/>
      <mass value="0.2734"/>
      <inertia ixx="0.000144463" ixy="0.0" ixz="0.0" iyy="0.000144463" iyz="0.0" izz="0.000263053"/>
    </inertial>
  </link>
  <joint name="RR_hip_rotor_joint" type="fixed">
    <origin rpy="0 0 0" xyz="-0.20205 -0.072 0"/>
    <parent link="base"/>
    <child link="RR_hip_rotor"/>
  </joint>
  <link
    name="RR_thigh">
    <inertial>
      <origin
        xyz="-0.006279 0.032049 -0.057835"
        rpy="0 0 0" />
      <mass
        value="4.536" />
      <inertia
        ixx="0.062299"
        ixy="-0.00087781"
        ixz="-0.0036475"
        iyy="0.061399"
        iyz="-0.0083537"
        izz="0.0081997" />
    </inertial>
    <visual>
      <origin
        xyz="0 0 0"
        rpy="0 0 0" />
      <geometry>
        <mesh
          filename="../meshes/RR_thigh.dae" />
      </geometry>
      <material
        name="">
        <color
          rgba="1 1 1 1" />
      </material>
    </visual>
    <collision>
      <origin rpy="0 1.57 0" xyz="-0.03 0 -0.2"/>
      <geometry>
        <box size="0.25 0.028 0.04"/>
      </geometry>
    </collision>
  </link>
  <joint
    name="RR_thigh_joint"
    type="revolute">
    <origin
      xyz="0 -0.11973 0"
      rpy="0 0 0" />
    <parent
      link="RR_hip" />
    <child
      link="RR_thigh" />
    <axis
      xyz="0 1 0" />
    <limit
      lower="-0.94"
      upper="4.69"
      effort="200"
      velocity="23" />
  </joint>
  <link name="RR_thigh_rotor">
    <!-- <visual>
      <origin rpy="1.5707963267948966 0 0" xyz="0 0 0"/>
      <geometry>
        <cylinder length="0.02" radius="0.05"/>
      </geometry>
    </visual> -->
    <collision>
      <origin rpy="1.5707963267948966 0 0" xyz="0 0 0"/>
      <geometry>
        <cylinder length="0.02" radius="0.05"/>
      </geometry>
    </collision>
    <inertial>
      <origin rpy="0 0 0" xyz="0.0 0.0 0.0"/>
      <mass value="0.2734"/>
      <inertia ixx="0.000144463" ixy="0.0" ixz="0.0" iyy="0.000144463" iyz="0.0" izz="0.000263053"/>
    </inertial>
  </link>
  <joint name="RR_thigh_rotor_joint" type="fixed">
    <origin rpy="0 0 0" xyz="0 0.00798 0"/>
    <parent link="RR_hip"/>
    <child link="RR_thigh_rotor"/>
  </joint>
  <link
    name="RR_calf">
    <inertial>
      <origin
        xyz="0.012422 0 -0.12499"
        rpy="0 0 0" />
      <mass
        value="0.404" />
      <inertia
        ixx="0.01143"
        ixy="0"
        ixz="0.000643"
        iyy="0.011534"
        iyz="0"
        izz="0.000331" />
    </inertial>
    <visual>
      <origin
        xyz="0 0 0"
        rpy="0 0 0" />
      <geometry>
        <mesh
          filename="../meshes/RR_calf.dae" />
      </geometry>
      <material
        name="">
        <color
          rgba="1 1 1 1" />
      </material>
    </visual>
    <collision>
      <origin rpy="0 1.2 0" xyz="-0.002 0 -0.03"/>
      <geometry>
        <box size="0.1 0.0245 0.018"/>
      </geometry>
    </collision>
    <collision>
      <origin rpy="0 1.35 0" xyz="0.022 0 -0.1"/>
      <geometry>
        <box size="0.1 0.0245 0.018"/>
      </geometry>
    </collision>
    <collision>
      <origin rpy="0 1.53 0" xyz="0.036 0 -0.225"/>
      <geometry>
        <box size="0.15 0.0245 0.015"/>
      </geometry>
    </collision>
    <collision>
      <origin rpy="0 2 0" xyz="0.023 0 -0.31"/>
      <geometry>
        <box size="0.05 0.028 0.035"/>
      </geometry>
    </collision>
  </link>
  <joint
    name="RR_calf_joint"
    type="revolute">
    <origin
      xyz="0 8.6986E-05 -0.35"
      rpy="0 0 0" />
    <parent
      link="RR_thigh" />
    <child
      link="RR_calf" />
    <axis
      xyz="0 1 0" />
    <limit
      lower="-2.82"
      upper="-0.43"
      effort="320"
      velocity="14" />
  </joint>
  <link name="RR_calf_rotor">
    <!-- <visual>
      <origin rpy="1.5707963267948966 0 0" xyz="0 0 0"/>
      <geometry>
        <cylinder length="0.02" radius="0.05"/>
      </geometry>
    </visual> -->
    <collision>
      <origin rpy="1.5707963267948966 0 0" xyz="0 0 0"/>
      <geometry>
        <cylinder length="0.02" radius="0.05"/>
      </geometry>
    </collision>
    <inertial>
      <origin rpy="0 0 0" xyz="0.0 0.0 0.0"/>
      <mass value="0.2734"/>
      <inertia ixx="0.000144463" ixy="0.0" ixz="0.0" iyy="0.000144463" iyz="0.0" izz="0.000263053"/>
    </inertial>
  </link>
  <joint name="RR_calf_rotor_joint" type="fixed">
    <origin rpy="0 0 0" xyz="0 0.05788 0"/>
    <parent link="RR_thigh"/>
    <child link="RR_calf_rotor"/>
  </joint>
  <link
    name="RR_foot">
    <inertial>
      <origin
        xyz="-0.006511 0 -0.010144"
        rpy="0 0 0" />
      <mass
        value="0.126" />
      <inertia
        ixx="3.8E-05"
        ixy="0"
        ixz="1.1E-05"
        iyy="4.1E-05"
        iyz="0"
        izz="4.2E-05" />
    </inertial>
    <collision>
      <origin
        xyz="0 0 0"
        rpy="1.57 0 0" />
      <geometry>
        <sphere radius="0.032" />
      </geometry>
    </collision>
  </link>
  <joint
    name="RR_foot_joint"
    type="fixed"
    dont_collapse="true">
    <origin
      xyz="0 -8.6984E-05 -0.35"
      rpy="0 0 0" />
    <parent
      link="RR_calf" />
    <child
      link="RR_foot" />
  </joint>
  <link
    name="f_oc_link">
    <inertial>
      <origin
        xyz="-3.39E-15 1.46E-16 -6.11E-16"
        rpy="0 0 0" />
      <mass
        value="4.19E-15" />
      <inertia
        ixx="1.68E-27"
        ixy="-3.89E-44"
        ixz="5.04E-44"
        iyy="1.68E-27"
        iyz="2.81E-45"
        izz="1.68E-27" />
    </inertial>
    <!-- <visual>
      <origin
        xyz="0 0 0"
        rpy="0 0 0" />
      <geometry>
        <mesh
          filename="../meshes/f_oc_link.STL" />
      </geometry>
      <material
        name="">
        <color
          rgba="1 1 1 1" />
      </material>
    </visual>
    <collision>
      <origin
        xyz="0 0 0"
        rpy="0 0 0" />
      <geometry>
        <mesh
          filename="../meshes/f_oc_link.STL" />
      </geometry>
    </collision> -->
  </link>
  <joint
    name="joint_f_oc"
    type="fixed">
    <origin
      xyz="0.39079 0 -0.013433"
      rpy="-1.5708 0 -1.5708" />
    <parent
      link="base" />
    <child
      link="f_oc_link" />
    <axis
      xyz="0 0 0" />
  </joint>
  <link
    name="r_oc_link">
    <inertial>
      <origin
        xyz="-0.39143 1.52E-07 -0.011961"
        rpy="0 0 0" />
      <mass
        value="4.19E-12" />
      <inertia
        ixx="1.68E-22"
        ixy="9.03E-39"
        ixz="0"
        iyy="1.68E-22"
        iyz="-1.2E-38"
        izz="1.68E-22" />
    </inertial>
    <!-- <visual>
      <origin
        xyz="0 0 0"
        rpy="0 0 0" />
      <geometry>
        <mesh
          filename="package://b2_z1/meshes/r_oc_link.STL" />
      </geometry>
      <material
        name="">
        <color
          rgba="1 1 1 1" />
      </material>
    </visual>
    <collision>
      <origin
        xyz="0 0 0"
        rpy="0 0 0" />
      <geometry>
        <mesh
          filename="package://b2_z1/meshes/r_oc_link.STL" />
      </geometry>
    </collision> -->
  </link>
  <joint
    name="joint_r_oc"
    type="fixed">
    <origin
      xyz="-0.38451 0 -0.023249"
      rpy="-1.5708 0 1.5708" />
    <parent
      link="base" />
    <child
      link="r_oc_link" />
    <axis
      xyz="0 0 0" />
  </joint>


    <!-- z1_gripper start -->
   <joint name="base_static_joint" type="fixed">
        <origin rpy="0 0 0" xyz="0.2 0 0.1"/>
        <parent link="base"/>
        <child link="link00"/>
    </joint>

    <link name="link00">
        <visual>
            <origin rpy="0 0 0" xyz="0 0 0"/>
            <geometry>
                <mesh filename="../meshes/z1/z1_Link00.dae" scale="1 1 1"/>
            </geometry>
        </visual>
        <!-- <collision>
            <geometry>
                <cylinder length="0.051" radius="0.0325"/>
            </geometry>
            <origin rpy="0 0 0" xyz="0 0 0.0255"/>
        </collision> -->
        <inertial>
            <origin rpy="0 0 0" xyz="-0.00334984 -0.00013615 0.02495843"/>
            <mass value="0.47247481"/>
            <inertia
                ixx="0.00037937" ixy="0.00000035" ixz="0.00001037"
                iyy="0.00041521" iyz="0.00000099"
                izz="0.00053066"/>
        </inertial>
    </link>

    <joint name="joint1" type="revolute">
        <origin rpy="0 0 0" xyz="0 0 0.0585"/>
        <parent link="link00"/>
        <child link="link01"/>
        <axis xyz="0 0 1"/>
        <dynamics damping="0.0" friction="0.0"/>
        <limit effort="30.0" velocity="10" lower="-2.618" upper="2.618"/>
    </joint>

    <link name="link01">
        <visual>
            <origin rpy="0 0 0" xyz="0 0 0"/>
            <geometry>
                <mesh filename="../meshes/z1/z1_Link01.dae" scale="1 1 1"/>
            </geometry>
        </visual>
        <!-- <collision>
            <geometry>
                <cylinder length="0.102" radius="0.0325"/>
            </geometry>
            <origin rpy="0 0 0" xyz="0 0 0"/>
        </collision> -->
        <inertial>
            <origin rpy="0 0 0" xyz="0.00000247 -0.00025198 0.02317169"/>
            <mass value="0.67332551"/>
            <inertia
                ixx="0.00128328" ixy="0.00000006" ixz="0.00000040"
                iyy="0.00071931" iyz="-0.00000050"
                izz="0.00083936"/>
        </inertial>
    </link>

    <joint name="joint2" type="revolute">
        <origin rpy="0 0 0" xyz="0 0 0.045"/>
        <parent link="link01"/>
        <child link="link02"/>
        <axis xyz="0 1 0"/>
        <dynamics damping="0.0" friction="0.0"/>
        <limit effort="60.0" velocity="10" lower="0.0" upper="3.14"/>
    </joint>

    <link name="link02">
        <visual>
            <origin rpy="0 0 0" xyz="0 0 0"/>
            <geometry>
                <mesh filename="../meshes/z1/z1_Link02.dae" scale="1 1 1"/>
            </geometry>
        </visual>
        <collision>
            <geometry>
                <cylinder length="0.102" radius="0.0325"/>
            </geometry>
            <origin rpy="1.57 0 0" xyz="0 0 0"/>
        </collision>
        <collision>
            <geometry>
                <cylinder length="0.235" radius="0.0225"/>
            </geometry>
            <origin rpy="0 1.57 0" xyz="-0.1625 0 0"/>
        </collision>
        <collision>
            <geometry>
                <cylinder length="0.051" radius="0.0325"/>
            </geometry>
            <origin rpy="1.57 0 0" xyz="-0.35 0 0"/>
        </collision>
        <inertial>
            <origin rpy="0 0 0" xyz="-0.11012601 0.00240029 0.00158266"/>
            <mass value="1.19132258"/>
            <inertia
                ixx="0.00102138" ixy="-0.00062358" ixz="-0.00000513"
                iyy="0.02429457" iyz="0.00000210"
                izz="0.02466114"/>
        </inertial>
    </link>

    <joint name="joint3" type="revolute">
        <origin rpy="0 0 0" xyz="-0.35 0 0"/>
        <parent link="link02"/>
        <child link="link03"/>
        <axis xyz="0 1 0"/>
        <dynamics damping="0.0" friction="0.0"/>
        <limit effort="30.0" velocity="10" lower="-4.78" upper="0.0"/>
    </joint>

    <link name="link03">
        <visual>
            <origin rpy="0 0 0" xyz="0 0 0"/>
            <geometry>
                <mesh filename="../meshes/z1/z1_Link03.dae" scale="1 1 1"/>
            </geometry>
        </visual>
        <collision>
            <geometry>
                <cylinder length="0.116" radius="0.02"/>
            </geometry>
            <origin rpy="0 1.57 0" xyz="0.128 0 0.055"/>
        </collision>
        <collision>
            <geometry>
                <cylinder length="0.059" radius="0.0325"/>
            </geometry>
            <origin rpy="0 1.57 0" xyz="0.2205 0 0.055"/>
        </collision>
        <inertial>
            <origin rpy="0 0 0" xyz="0.10609208 -0.00541815 0.03476383"/>
            <mass value="0.83940874"/>
            <inertia
                ixx="0.00108061" ixy="0.00008669" ixz="0.00208102"
                iyy="0.00954238" iyz="0.00001332"
                izz="0.00886621"/>
        </inertial>
    </link>

    <joint name="joint4" type="revolute">
        <origin rpy="0 0 0" xyz="0.218 0 0.057"/>
        <parent link="link03"/>
        <child link="link04"/>
        <axis xyz="0 1 0"/>
        <dynamics damping="0.0" friction="0.0"/>
        <limit effort="30.0" velocity="10" lower="-1.744" upper="1.57"/>
    </joint>

    <link name="link04">
        <visual>
            <origin rpy="0 0 0" xyz="0 0 0"/>
            <geometry>
                <mesh filename="../meshes/z1/z1_Link04.dae" scale="1 1 1"/>
            </geometry>
        </visual>
        <!-- <collision>
            <geometry>
                <cylinder length="0.073" radius="0.0325"/>
            </geometry>
            <origin rpy="1.57 0 0" xyz="0.0472 0 0"/>
        </collision> -->
        <inertial>
            <origin rpy="0 0 0" xyz="0.04366681 0.00364738 -0.00170192"/>
            <mass value="0.56404563"/>
            <inertia
                ixx="0.00031576" ixy="-0.00008130" ixz="-0.00004091"
                iyy="0.00092996" iyz="0.00000596"
                izz="0.00097912"/>
        </inertial>
    </link>

    <joint name="joint5" type="revolute">
        <origin rpy="0 0 0" xyz="0.07 0.0 0.0"/>
        <parent link="link04"/>
        <child link="link05"/>
        <axis xyz="0 0 1"/>
        <dynamics damping="0.0" friction="0.0"/>
        <limit effort="30.0" velocity="10" lower="-1.727" upper="1.727"/>
    </joint>

    <link name="link05">
        <visual>
            <origin rpy="0 0 0" xyz="0 0 0"/>
            <geometry>
                <mesh filename="../meshes/z1/z1_Link05.dae" scale="1 1 1"/>
            </geometry>
        </visual>
        <!-- <collision>
            <origin rpy="0 0 0" xyz="0 0 0"/>
            <geometry>
                <mesh filename="../meshes/z1/z1_Link05.dae" scale="1 1 1"/>
            </geometry>
        </collision> -->
        <inertial>
            <origin rpy="0 0 0" xyz="0.03121533 0.0 0.00646316"/>
            <mass value="0.38938492"/>
            <inertia
                ixx="0.00017605" ixy="-0.00000040" ixz="-0.00005689"
                iyy="0.00055896" iyz="0.00000013"
                izz="0.00053860"/>
        </inertial>
    </link>

    <joint name="joint6" type="revolute">
        <origin rpy="0 0 0" xyz="0.0492 0.0 0.0"/>
        <parent link="link05"/>
        <child link="link06"/>
        <axis xyz="1 0 0"/>
        <dynamics damping="0.0" friction="0.0"/>
        <limit effort="30.0" velocity="10" lower="-2.79" upper="2.79"/>
    </joint>

    <link name="link06">
        <visual>
            <origin rpy="0 0 0" xyz="0 0 0"/>
            <geometry>
                <mesh filename="../meshes/z1/z1_Link06.dae" scale="1 1 1"/>
            </geometry>
        </visual>
        <collision>
            <geometry>
                <cylinder length="0.051" radius="0.0325"/>
            </geometry>
            <origin rpy="0 1.57 0" xyz="0.0255 0 0"/>
        </collision>
        <inertial>
            <origin rpy="0 0 0" xyz="0.02415690 -0.00017355 -0.00143876"/>
            <mass value="0.28875807"/>
            <inertia
                ixx="0.00018328" ixy="-0.00000122" ixz="-0.00000054"
                iyy="0.00014750" iyz="-0.00000008"
                izz="0.00014680"/>
        </inertial>
    </link>

        <joint name="gripperStator" type="fixed">
            <origin rpy="0 0 0" xyz="0.051 0.0 0.0"/>
            <parent link="link06"/>
            <child link="gripperStator"/>
        </joint>

        <link name="gripperStator">
            <visual>
                <origin rpy="0 0 0" xyz="0 0 0"/>
                <geometry>
                    <mesh filename="../meshes/z1/z1_GripperStator.dae" scale="1 1 1"/>
                </geometry>
            </visual>
            <!-- <collision>
                <geometry>
                    <cylinder length="0.051" radius="0.0325"/>
                </geometry>
                <origin rpy="0 0 0" xyz="0 0 0"/>
            </collision> -->
            <!-- <collision>
                <origin rpy="0 0 0" xyz="0 0 0"/>
                <geometry>
                    <mesh filename="../meshes/z1/z1_GripperStator.dae" scale="1 1 1"/>
                </geometry>
            </collision> -->

            <inertial>
                <origin rpy="0 0 0" xyz="0.04764427 -0.00035819 -0.00249162"/>
                <mass value="0.52603655"/>
                <inertia
                    ixx="0.00038683" ixy="0.00000359" ixz="-0.00007662"
                    iyy="0.00068614" iyz="-0.00000209"
                    izz="0.00066293"/>
            </inertial>
        </link>

        <joint name="jointGripper" type="revolute">
            <origin rpy="0 0 0" xyz="0.049 0.0 0"/>
            <parent link="gripperStator"/>
            <child link="gripperMover"/>
            <axis xyz="0 1 0"/>
            <dynamics damping="0.0" friction="0.0"/>
            <limit effort="30.0" velocity="10" lower="-1.57" upper="0.0"/>
        </joint>

        <link name="gripperMover">
            <visual>
                <origin rpy="0 0 0" xyz="0 0 0"/>
                <geometry>
                    <mesh filename="../meshes/z1/z1_GripperMover.dae" scale="1 1 1"/>
                </geometry>
            </visual>
            <!-- <collision>
                <origin rpy="0 0 0" xyz="0 0 0"/>
                <geometry>
                    <mesh filename="../meshes/z1/z1_GripperMover.dae" scale="1 1 1"/>
                </geometry>
            </collision> -->
            <inertial>
                <origin rpy="0 0 0" xyz="0.01320633 0.00476708 0.00380534"/>
                <mass value="0.27621302"/>
                <inertia
                    ixx="0.00017716" ixy="-0.00001683" ixz="0.00001786"
                    iyy="0.00026787" iyz="-0.00000262"
                    izz="0.00035728"/>
            </inertial>
        </link>
        
  <transmission name="JointTrans1">
      <type>transmission_interface/SimpleTransmission</type>
      <joint name="joint1">
        <hardwareInterface>hardware_interface/EffortJointInterface</hardwareInterface>
      </joint>
      <actuator name="Actuator1">
        <hardwareInterface>hardware_interface/EffortJointInterface</hardwareInterface>
        <mechanicalReduction>1</mechanicalReduction>
      </actuator>
    </transmission>
    <transmission name="JointTrans2">
      <type>transmission_interface/SimpleTransmission</type>
      <joint name="joint2">
        <hardwareInterface>hardware_interface/EffortJointInterface</hardwareInterface>
      </joint>
      <actuator name="Actuator2">
        <hardwareInterface>hardware_interface/EffortJointInterface</hardwareInterface>
        <mechanicalReduction>1</mechanicalReduction>
      </actuator>
    </transmission>
    <transmission name="JointTrans3">
      <type>transmission_interface/SimpleTransmission</type>
      <joint name="joint3">
        <hardwareInterface>hardware_interface/EffortJointInterface</hardwareInterface>
      </joint>
      <actuator name="Actuator3">
        <hardwareInterface>hardware_interface/EffortJointInterface</hardwareInterface>
        <mechanicalReduction>1</mechanicalReduction>
      </actuator>
    </transmission>
    <transmission name="JointTrans4">
      <type>transmission_interface/SimpleTransmission</type>
      <joint name="joint4">
        <hardwareInterface>hardware_interface/EffortJointInterface</hardwareInterface>
      </joint>
      <actuator name="Actuator4">
        <hardwareInterface>hardware_interface/EffortJointInterface</hardwareInterface>
        <mechanicalReduction>1</mechanicalReduction>
      </actuator>
    </transmission>
    <transmission name="JointTrans5">
      <type>transmission_interface/SimpleTransmission</type>
      <joint name="joint5">
        <hardwareInterface>hardware_interface/EffortJointInterface</hardwareInterface>
      </joint>
      <actuator name="Actuator5">
        <hardwareInterface>hardware_interface/EffortJointInterface</hardwareInterface>
        <mechanicalReduction>1</mechanicalReduction>
      </actuator>
    </transmission>
    <transmission name="JointTrans6">
      <type>transmission_interface/SimpleTransmission</type>
      <joint name="joint6">
        <hardwareInterface>hardware_interface/EffortJointInterface</hardwareInterface>
      </joint>
      <actuator name="Actuator6">
        <hardwareInterface>hardware_interface/EffortJointInterface</hardwareInterface>
        <mechanicalReduction>1</mechanicalReduction>
      </actuator>
    </transmission>
</robot>
